concurrent.futures.process._RemoteTraceback: 
"""
Traceback (most recent call last):
  File "/opt/h2oai/dai/python/lib/python3.6/concurrent/futures/process.py", line 175, in _process_worker
    r = call_item.fn(*call_item.args, **call_item.kwargs)
  File "h2oaicore/systemutils.py", line 4425, in h2oaicore.systemutils.traced_func_without_task_or_usesgpu
  File "h2oaicore/systemutils.py", line 4365, in h2oaicore.systemutils._traced_func
  File "h2oaicore/systemutils.py", line 4353, in h2oaicore.systemutils._traced_func
  File "h2oaicore/auto_dl.py", line 383, in h2oaicore.auto_dl.do_auto_dl_subprocess
  File "h2oaicore/auto_dl_utils.py", line 341, in h2oaicore.auto_dl_utils.load_dataset
  File "h2oaicore/systemutils.py", line 5150, in h2oaicore.systemutils.read_data
h2oaicore.systemutils.InvalidDataError: Path to data '' does not exist.
"""

The above exception was the direct cause of the following exception:

Traceback (most recent call last):
  File "h2oaicore/systemutils.py", line 1696, in h2oaicore.systemutils.mppool.try_get_internal
  File "/opt/h2oai/dai/python/lib/python3.6/concurrent/futures/_base.py", line 425, in result
    return self.__get_result()
  File "/opt/h2oai/dai/python/lib/python3.6/concurrent/futures/_base.py", line 384, in __get_result
    raise self._exception
h2oaicore.systemutils.InvalidDataError: Path to data '' does not exist.
